Workbook

Sheet Master Plan
A1: MASTER PLAN DỰ ÁN – SỐ HOÁ QUY TRÌNH BẢO HÀNH – BẢO DƯỠNG ĐIỆN TỬ ĐIỆN LẠNH ABC
A2: Kế hoạch triển khai chi tiết | App Mobile Khách hàng & Web Hệ thống Quản trị Trung tâm
A3: Ngày bắt đầu dự án: 13/07/2026 | D3: Go-live dự kiến: 13/01/2027 | H3: Kết thúc bảo hành hỗ trợ: 12/04/2027
A5: STT | B5: GĐ | C5: Giai đoạn / Nhóm công việc | D5: Nội dung công việc triển khai | E5: Người phụ trách | F5: Ngày thực tế bắt đầu | G5: Kế hoạch lần 1 | I5: Số ngày làm việc | J5: Kế hoạch lần … | L5: Đầu ra | M5: Ghi chú | N5: Tiến độ | O5: Trạng thái | P5: Khó khăn/ Rủi ro | Q5: Đề xuất
G6: Ngày bắt đầu | H6: Ngày kết thúc | J6: Ngày bắt đầu | K6: Ngày kết thúc
A7: 1 | B7: 1 | C7: Kickoff dự án | D7: Họp kickoff dự án với đầy đủ các bên | E7: PM, Toàn đội dự án, PC | G7: 46216 | H7: =WORKDAY(G7,I7) - 1 -> 46216 | I7: 1 | L7: Biên bản kickoff, Project Charter, RACI | N7: 100 | O7: Hoàn thành
A8: 2 | B8: 2 | C8: Khảo sát & thu thập yêu cầu | D8: Lên kế hoạch khảo sát, chuẩn bị bảng câu hỏi | E8: PM, BA | G8: 46216 | H8: =WORKDAY(G8,I8) - 1 -> 46217 | I8: 2 | L8: Kế hoạch khảo sát, bảng câu hỏi phỏng vấn | N8: 80 | O8: Trễ hạn
A9: 3 | D9: Phỏng vấn các bên liên quan (Quản lý, Tiếp nhận, Điều phối, Thủ kho, Thợ, Kế toán) | E9: BA | G9: 46218 | H9: =WORKDAY(G9,I9) - 1 -> 46224 | I9: 5 | L9: Biên bản phỏng vấn từng bộ phận | N9: 10 | O9: Đang thực hiện
A10: 4 | D10: Khảo sát quy trình hiện tại, thu thập biểu mẫu/phiếu bảo hành | E10: BA | G10: 46218 | H10: =WORKDAY(G10,I10) - 1 -> 46224 | I10: 5 | L10: Sơ đồ quy trình hiện tại (As-is Process Map) | N10: 0 | O10: Chưa bắt đầu
A11: 5 | D11: Tổng hợp báo cáo khảo sát & danh sách yêu cầu sơ bộ | E11: BA | G11: 46225 | H11: =WORKDAY(G11,I11) - 1 -> 46229 | I11: 3 | L11: Biên bản khảo sát, Requirement List sơ bộ | N11: 0 | O11: Chưa bắt đầu
A12: 6 | B12: 3 | C12: Phân tích nghiệp vụ & Thiết kế giải pháp | D12: Thiết kế quy trình nghiệp vụ mới (To-be / BPMN) | E12: BA | G12: 46230 | H12: =WORKDAY(G12,I12) - 1 -> 46232 | I12: 3 | L12: Sơ đồ quy trình nghiệp vụ mới (BPMN) | N12: 0 | O12: Chưa bắt đầu
A13: 7 | D13: Thiết kế wireframe & mockup UI/UX (App + Web) | E13: UI/UX Designer, BA | G13: 46230 | H13: =WORKDAY(G13,I13) - 1 -> 46237 | I13: 6 | L13: Wireframe & Mockup UI/UX | N13: 0 | O13: Chưa bắt đầu
A14: 8 | D14: Thiết kế mô hình dữ liệu (ERD) | E14: Technical Lead | G14: 46233 | H14: =WORKDAY(G14,I14) - 1 -> 46237 | I14: 3 | L14: Sơ đồ dữ liệu ERD | N14: 0 | O14: Chưa bắt đầu
A15: 9 | D15: Phác thảo kiến trúc hệ thống tổng thể & phân quyền người dùng | E15: Technical Lead | G15: 46238 | H15: =WORKDAY(G15,I15) - 1 -> 46243 | I15: 4 | L15: Sơ đồ kiến trúc hệ thống (bản thiết kế nháp, dùng nội bộ) | N15: 0 | O15: Chưa bắt đầu
A16: 10 | B16: 4 | C16: Soạn thảo tài liệu | D16: Soạn BRD (Business Requirement Document) | E16: BA | G16: 46244 | H16: =WORKDAY(G16,I16) - 1 -> 46246 | I16: 3 | L16: Tài liệu BRD | N16: 0 | O16: Chưa bắt đầu
A17: 11 | D17: Soạn SRS & Use case chi tiết | E17: BA | G17: 46247 | H17: =WORKDAY(G17,I17) - 1 -> 46252 | I17: 4 | L17: Tài liệu SRS | N17: 0 | O17: Chưa bắt đầu
A18: 12 | D18: Hoàn thiện tài liệu UI/UX & Prototype tương tác | E18: UI/UX Designer | G18: 46244 | H18: =WORKDAY(G18,I18) - 1 -> 46250 | I18: 5 | L18: Prototype tương tác + tài liệu UI/UX | N18: 0 | O18: Chưa bắt đầu
A19: 13 | D19: Soạn tài liệu kiến trúc hệ thống & API specification | E19: Technical Lead | G19: 46244 | H19: =WORKDAY(G19,I19) - 1 -> 46250 | I19: 5 | L19: Tài liệu kiến trúc & API spec | N19: 0 | O19: Chưa bắt đầu
A20: 14 | D20: Soạn kế hoạch kiểm thử tổng thể (Test Strategy) | E20: QA Lead | G20: 46247 | H20: =WORKDAY(G20,I20) - 1 -> 46251 | I20: 3 | L20: Test Strategy | N20: 0 | O20: Chưa bắt đầu
A21: 15 | B21: 5 | C21: Review & Confirm tài liệu | D21: Trình bày tài liệu cho khách hàng & các phòng ban liên quan | E21: PM, BA | G21: 46252 | H21: =WORKDAY(G21,I21) - 1 -> 46252 | I21: 1 | L21: Buổi trình bày tài liệu | N21: 0 | O21: Chưa bắt đầu
A22: 16 | D22: Thu thập góp ý & chỉnh sửa (vòng 1) | E22: BA, Designer, Tech Lead | G22: 46253 | H22: =WORKDAY(G22,I22) - 1 -> 46254 | I22: 2 | L22: Tài liệu bản chỉnh sửa vòng 1 | N22: 0 | O22: Chưa bắt đầu
A23: 17 | D23: Thu thập góp ý & chỉnh sửa (vòng 2 - nếu cần) | E23: BA | G23: 46255 | H23: =WORKDAY(G23,I23) - 1 -> 46258 | I23: 2 | L23: Tài liệu bản chỉnh sửa vòng 2 | N23: 0 | O23: Chưa bắt đầu
A24: 18 | D24: Khách hàng ký xác nhận (sign-off) tài liệu | E24: PM, Đại diện Trung tâm ABC | G24: 46259 | H24: =WORKDAY(G24,I24) - 1 -> 46259 | I24: 1 | L24: Tài liệu final có chữ ký xác nhận | N24: 0 | O24: Chưa bắt đầu
A25: 19 | B25: 6 | C25: Chuyển giao cho đội phát triển (Transfer) | D25: Bàn giao tài liệu, giải thích chi tiết cho Dev/QA/Designer Lead | E25: BA, Technical Lead | G25: 46260 | H25: =WORKDAY(G25,I25) - 1 -> 46260 | I25: 1 | L25: Buổi bàn giao tài liệu | N25: 0 | O25: Chưa bắt đầu
A26: 20 | D26: Phân rã Epic → User Story, xây dựng Product Backlog | E26: BA, Dev Lead | G26: 46261 | H26: =WORKDAY(G26,I26) - 1 -> 46264 | I26: 2 | L26: Product Backlog | N26: 0 | O26: Chưa bắt đầu
A27: 21 | D27: Chuẩn bị môi trường Dev/Staging, repository, CI/CD cơ bản | E27: Dev Lead | G27: 46261 | H27: =WORKDAY(G27,I27) - 1 -> 46265 | I27: 3 | L27: Môi trường kỹ thuật sẵn sàng | N27: 0 | O27: Chưa bắt đầu
A28: 22 | D28: Ước lượng effort & xác định velocity dự kiến | E28: Toàn đội Dev | G28: 46264 | H28: =WORKDAY(G28,I28) - 1 -> 46265 | I28: 2 | L28: Backlog đã ước lượng story point | N28: 0 | O28: Chưa bắt đầu
A29: 23 | B29: 7 | C29: Phát triển - Sprint 0 (Chuẩn bị) | D29: Setup hạ tầng, Design System, Authentication & phân quyền cơ bản | E29: Đội Dev | G29: 46266 | H29: =WORKDAY(G29,I29) - 1 -> 46272 | I29: 5 | L29: Hạ tầng kỹ thuật, module đăng nhập | N29: 0 | O29: Chưa bắt đầu
A30: 24 | D30: App: Đặt lịch bảo hành/bảo dưỡng | Web: Tiếp nhận đơn (từ App + walk-in) | E30: Đội Dev | G30: 46273 | H30: =WORKDAY(G30,I30) - 1 -> 46286 | I30: 10 | L30: Increment Sprint 1 (demo cuối sprint) | N30: 0 | O30: Chưa bắt đầu
A31: 25 | D31: Web: Kỹ thuật đánh giá phương án sửa chữa & lập báo giá | App: Khách hàng xem báo giá, xác nhận & thanh toán (online / tiền mặt) | E31: Đội Dev | G31: 46287 | H31: =WORKDAY(G31,I31)-1 -> 46300 | I31: 10 | L31: Increment Sprint 2 (demo cuối sprint) | N31: 0 | O31: Chưa bắt đầu
A32: 26 | D32: Web: Điều phối thợ theo khu vực/lịch rảnh, hồ sơ & chấm công thợ | App: Hiển thị trạng thái đơn real-time | E32: Đội Dev | G32: 46301 | H32: =WORKDAY(G32,I32)-1 -> 46314 | I32: 10 | L32: Increment Sprint 3 (demo cuối sprint) | N32: 0 | O32: Chưa bắt đầu
A33: 27 | D33: App: Theo dõi tiến độ chi tiết, lịch sử dịch vụ, thông báo | Web: Nhật ký xử lý đơn & hồ sơ khách hàng (CRM) | E33: Đội Dev | G33: 46315 | H33: =WORKDAY(G33,I33)-1 -> 46328 | I33: 10 | L33: Increment Sprint 4 (demo cuối sprint) | N33: 0 | O33: Chưa bắt đầu
A34: 28 | D34: Web: Quản lý kho linh kiện (danh mục, tồn kho, nhập kho, cảnh báo tồn thấp) | E34: Đội Dev | G34: 46329 | H34: =WORKDAY(G34,I34)-1 -> 46342 | I34: 10 | L34: Increment Sprint 5 (demo cuối sprint) | N34: 0 | O34: Chưa bắt đầu
A35: 29 | D35: Web: Cấp phát linh kiện cho thợ, đối soát | App: Xem chi tiết linh kiện & chi phí | E35: Đội Dev | G35: 46343 | H35: =WORKDAY(G35,I35)-1 -> 46356 | I35: 10 | L35: Increment Sprint 6 (demo cuối sprint) | N35: 0 | O35: Chưa bắt đầu
A36: 30 | D36: App: Đánh giá dịch vụ | Web: Dashboard báo cáo, quản trị người dùng/phân quyền, nhật ký hoạt động (audit log), KPI thợ | E36: Đội Dev | G36: 46357 | H36: =WORKDAY(G36,I36)-1 -> 46370 | I36: 10 | L36: Increment Sprint 7 (demo cuối sprint) | N36: 0 | O36: Chưa bắt đầu
A37: 31 | D37: Tối ưu hiệu năng, hoàn thiện UX, rà soát bảo mật, fix bug tồn đọng | E37: Đội Dev, QA | G37: 46371 | H37: =WORKDAY(G37,I37)-1 -> 46384 | I37: 10 | L37: Bản build ổn định, sẵn sàng SIT/UAT | N37: 0 | O37: Chưa bắt đầu
A38: 32 | B38: 8 | C38: Kiểm thử hệ thống (SIT/UAT) | D38: SIT - Kiểm thử tích hợp App ↔ Backend ↔ Web | E38: QA | G38: 46385 | H38: =WORKDAY(G38,I38)-1 -> 46390 | I38: 4 | L38: Test Report SIT | N38: 0 | O38: Chưa bắt đầu
A39: 33 | D39: UAT - Người dùng thực tế thử nghiệm theo kịch bản | E39: QA, Đại diện Trung tâm ABC | G39: 46391 | H39: =WORKDAY(G39,I39)-1 -> 46394 | I39: 4 | L39: Bug Tracking Log, kịch bản UAT đã chạy | N39: 0 | O39: Chưa bắt đầu
A40: 34 | D40: Fix lỗi & retest theo mức độ ưu tiên | E40: Đội Dev, QA | G40: 46393 | H40: =WORKDAY(G40,I40)-1 -> 46397 | I40: 3 | L40: Bug đã fix & retest | N40: 0 | O40: Chưa bắt đầu
A41: 35 | D41: Xác nhận UAT Pass từ khách hàng | E41: Đại diện Trung tâm ABC | G41: 46398 | H41: =WORKDAY(G41,I41)-1 -> 46398 | I41: 1 | L41: Biên bản xác nhận UAT Pass | N41: 0 | O41: Chưa bắt đầu
...

Sheet Gantt Chart
A1: GANTT CHART — MASTER PLAN Dự án Số hoá Quy trình Bảo hành – Bảo dưỡng ABC
A2: Dữ liệu liên kết trực tiếp từ sheet 'Master Plan' — cập nhật ngày/trạng thái bên đó sẽ tự động phản ánh lại ở đây.
A4: STT | B4: Giai đoạn | C4: Công việc | D4: Bắt đầu | E4: Kết thúc | F4: Số ngày | G4: Tiến độ (%) | H4: Đã xong (ngày) | I4: Còn lại (ngày)
A5: ='Master Plan'!A7 -> 1 | B5: ='Master Plan'!C7 -> Kickoff dự án | C5: ='Master Plan'!D7 -> Họp kickoff dự án với đầy đủ các bên | D5: ='Master Plan'!G7 -> 46216 | E5: ='Master Plan'!H7 -> 46216 | F5: =E5-D5+1 -> 1 | G5: ='Master Plan'!N7/100 -> 1 | H5: =ROUND(F5*G5,2) -> 1 | I5: =F5-H5 -> 0
A6: ='Master Plan'!A8 -> 2 | B6: ='Master Plan'!C8 -> Khảo sát & thu thập yêu cầu | C6: ='Master Plan'!D8 -> Lên kế hoạch khảo sát, chuẩn bị bảng câu hỏi | D6: ='Master Plan'!G8 -> 46216 | E6: ='Master Plan'!H8 -> 46217 | F6: =E6-D6+1 -> 2 | G6: ='Master Plan'!N8/100 -> 0.8 | H6: =ROUND(F6*G6,2) -> 1.6 | I6: =F6-H6 -> 0.4
A7: ='Master Plan'!A9 -> 3 | B7: ='Master Plan'!C8 -> Khảo sát & thu thập yêu cầu | C7: ='Master Plan'!D9 -> Phỏng vấn các bên liên quan (Quản lý, Tiếp nhận, Điều phối, Thủ kho, Thợ, Kế toán) | D7: ='Master Plan'!G9 -> 46218 | E7: ='Master Plan'!H9 -> 46224 | F7: =E7-D7+1 -> 7 | G7: ='Master Plan'!N9/100 -> 0.1 | H7: =ROUND(F7*G7,2) -> 0.7 | I7: =F7-H7 -> 6.3
A8: ='Master Plan'!A10 -> 4 | B8: ='Master Plan'!C8 -> Khảo sát & thu thập yêu cầu | C8: ='Master Plan'!D10 -> Khảo sát quy trình hiện tại, thu thập biểu mẫu/phiếu bảo hành | D8: ='Master Plan'!G10 -> 46218 | E8: ='Master Plan'!H10 -> 46224 | F8: =E8-D8+1 -> 7 | G8: ='Master Plan'!N10/100 -> 0 | H8: =ROUND(F8*G8,2) -> 0 | I8: =F8-H8 -> 7
A9: ='Master Plan'!A11 -> 5 | B9: ='Master Plan'!C8 -> Khảo sát & thu thập yêu cầu | C9: ='Master Plan'!D11 -> Tổng hợp báo cáo khảo sát & danh sách yêu cầu sơ bộ | D9: ='Master Plan'!G11 -> 46225 | E9: ='Master Plan'!H11 -> 46229 | F9: =E9-D9+1 -> 5 | G9: ='Master Plan'!N11/100 -> 0 | H9: =ROUND(F9*G9,2) -> 0 | I9: =F9-H9 -> 5
A10: ='Master Plan'!A12 -> 6 | B10: ='Master Plan'!C12 -> Phân tích nghiệp vụ & Thiết kế giải pháp | C10: ='Master Plan'!D12 -> Thiết kế quy trình nghiệp vụ mới (To-be / BPMN) | D10: ='Master Plan'!G12 -> 46230 | E10: ='Master Plan'!H12 -> 46232 | F10: =E10-D10+1 -> 3 | G10: ='Master Plan'!N12/100 -> 0 | H10: =ROUND(F10*G10,2) -> 0 | I10: =F10-H10 -> 3
A11: ='Master Plan'!A13 -> 7 | B11: ='Master Plan'!C12 -> Phân tích nghiệp vụ & Thiết kế giải pháp | C11: ='Master Plan'!D13 -> Thiết kế wireframe & mockup UI/UX (App + Web) | D11: ='Master Plan'!G13 -> 46230 | E11: ='Master Plan'!H13 -> 46237 | F11: =E11-D11+1 -> 8 | G11: ='Master Plan'!N13/100 -> 0 | H11: =ROUND(F11*G11,2) -> 0 | I11: =F11-H11 -> 8
A12: ='Master Plan'!A14 -> 8 | B12: ='Master Plan'!C12 -> Phân tích nghiệp vụ & Thiết kế giải pháp | C12: ='Master Plan'!D14 -> Thiết kế mô hình dữ liệu (ERD) | D12: ='Master Plan'!G14 -> 46233 | E12: ='Master Plan'!H14 -> 46237 | F12: =E12-D12+1 -> 5 | G12: ='Master Plan'!N14/100 -> 0 | H12: =ROUND(F12*G12,2) -> 0 | I12: =F12-H12 -> 5
A13: ='Master Plan'!A15 -> 9 | B13: ='Master Plan'!C12 -> Phân tích nghiệp vụ & Thiết kế giải pháp | C13: ='Master Plan'!D15 -> Phác thảo kiến trúc hệ thống tổng thể & phân quyền người dùng | D13: ='Master Plan'!G15 -> 46238 | E13: ='Master Plan'!H15 -> 46243 | F13: =E13-D13+1 -> 6 | G13: ='Master Plan'!N15/100 -> 0 | H13: =ROUND(F13*G13,2) -> 0 | I13: =F13-H13 -> 6
A14: ='Master Plan'!A16 -> 10 | B14: ='Master Plan'!C16 -> Soạn thảo tài liệu | C14: ='Master Plan'!D16 -> Soạn BRD (Business Requirement Document) | D14: ='Master Plan'!G16 -> 46244 | E14: ='Master Plan'!H16 -> 46246 | F14: =E14-D14+1 -> 3 | G14: ='Master Plan'!N16/100 -> 0 | H14: =ROUND(F14*G14,2) -> 0 | I14: =F14-H14 -> 3
A15: ='Master Plan'!A17 -> 11 | B15: ='Master Plan'!C16 -> Soạn thảo tài liệu | C15: ='Master Plan'!D17 -> Soạn SRS & Use case chi tiết | D15: ='Master Plan'!G17 -> 46247 | E15: ='Master Plan'!H17 -> 46252 | F15: =E15-D15+1 -> 6 | G15: ='Master Plan'!N17/100 -> 0 | H15: =ROUND(F15*G15,2) -> 0 | I15: =F15-H15 -> 6
A16: ='Master Plan'!A18 -> 12 | B16: ='Master Plan'!C16 -> Soạn thảo tài liệu | C16: ='Master Plan'!D18 -> Hoàn thiện tài liệu UI/UX & Prototype tương tác | D16: ='Master Plan'!G18 -> 46244 | E16: ='Master Plan'!H18 -> 46250 | F16: =E16-D16+1 -> 7 | G16: ='Master Plan'!N18/100 -> 0 | H16: =ROUND(F16*G16,2) -> 0 | I16: =F16-H16 -> 7
A17: ='Master Plan'!A19 -> 13 | B17: ='Master Plan'!C16 -> Soạn thảo tài liệu | C17: ='Master Plan'!D19 -> Soạn tài liệu kiến trúc hệ thống & API specification | D17: ='Master Plan'!G19 -> 46244 | E17: ='Master Plan'!H19 -> 46250 | F17: =E17-D17+1 -> 7 | G17: ='Master Plan'!N19/100 -> 0 | H17: =ROUND(F17*G17,2) -> 0 | I17: =F17-H17 -> 7
A18: ='Master Plan'!A20 -> 14 | B18: ='Master Plan'!C16 -> Soạn thảo tài liệu | C18: ='Master Plan'!D20 -> Soạn kế hoạch kiểm thử tổng thể (Test Strategy) | D18: ='Master Plan'!G20 -> 46247 | E18: ='Master Plan'!H20 -> 46251 | F18: =E18-D18+1 -> 5 | G18: ='Master Plan'!N20/100 -> 0 | H18: =ROUND(F18*G18,2) -> 0 | I18: =F18-H18 -> 5
A19: ='Master Plan'!A21 -> 15 | B19: ='Master Plan'!C21 -> Review & Confirm tài liệu | C19: ='Master Plan'!D21 -> Trình bày tài liệu cho khách hàng & các phòng ban liên quan | D19: ='Master Plan'!G21 -> 46252 | E19: ='Master Plan'!H21 -> 46252 | F19: =E19-D19+1 -> 1 | G19: ='Master Plan'!N21/100 -> 0 | H19: =ROUND(F19*G19,2) -> 0 | I19: =F19-H19 -> 1
A20: ='Master Plan'!A22 -> 16 | B20: ='Master Plan'!C21 -> Review & Confirm tài liệu | C20: ='Master Plan'!D22 -> Thu thập góp ý & chỉnh sửa (vòng 1) | D20: ='Master Plan'!G22 -> 46253 | E20: ='Master Plan'!H22 -> 46254 | F20: =E20-D20+1 -> 2 | G20: ='Master Plan'!N22/100 -> 0 | H20: =ROUND(F20*G20,2) -> 0 | I20: =F20-H20 -> 2
A21: ='Master Plan'!A23 -> 17 | B21: ='Master Plan'!C21 -> Review & Confirm tài liệu | C21: ='Master Plan'!D23 -> Thu thập góp ý & chỉnh sửa (vòng 2 - nếu cần) | D21: ='Master Plan'!G23 -> 46255 | E21: ='Master Plan'!H23 -> 46258 | F21: =E21-D21+1 -> 4 | G21: ='Master Plan'!N23/100 -> 0 | H21: =ROUND(F21*G21,2) -> 0 | I21: =F21-H21 -> 4
A22: ='Master Plan'!A24 -> 18 | B22: ='Master Plan'!C21 -> Review & Confirm tài liệu | C22: ='Master Plan'!D24 -> Khách hàng ký xác nhận (sign-off) tài liệu | D22: ='Master Plan'!G24 -> 46259 | E22: ='Master Plan'!H24 -> 46259 | F22: =E22-D22+1 -> 1 | G22: ='Master Plan'!N24/100 -> 0 | H22: =ROUND(F22*G22,2) -> 0 | I22: =F22-H22 -> 1
A23: ='Master Plan'!A25 -> 19 | B23: ='Master Plan'!C25 -> Chuyển giao cho đội phát triển (Transfer) | C23: ='Master Plan'!D25 -> Bàn giao tài liệu, giải thích chi tiết cho Dev/QA/Designer Lead | D23: ='Master Plan'!G25 -> 46260 | E23: ='Master Plan'!H25 -> 46260 | F23: =E23-D23+1 -> 1 | G23: ='Master Plan'!N25/100 -> 0 | H23: =ROUND(F23*G23,2) -> 0 | I23: =F23-H23 -> 1
A24: ='Master Plan'!A26 -> 20 | B24: ='Master Plan'!C25 -> Chuyển giao cho đội phát triển (Transfer) | C24: ='Master Plan'!D26 -> Phân rã Epic → User Story, xây dựng Product Backlog | D24: ='Master Plan'!G26 -> 46261 | E24: ='Master Plan'!H26 -> 46264 | F24: =E24-D24+1 -> 4 | G24: ='Master Plan'!N26/100 -> 0 | H24: =ROUND(F24*G24,2) -> 0 | I24: =F24-H24 -> 4
A25: ='Master Plan'!A27 -> 21 | B25: ='Master Plan'!C25 -> Chuyển giao cho đội phát triển (Transfer) | C25: ='Master Plan'!D27 -> Chuẩn bị môi trường Dev/Staging, repository, CI/CD cơ bản | D25: ='Master Plan'!G27 -> 46261 | E25: ='Master Plan'!H27 -> 46265 | F25: =E25-D25+1 -> 5 | G25: ='Master Plan'!N27/100 -> 0 | H25: =ROUND(F25*G25,2) -> 0 | I25: =F25-H25 -> 5
A26: ='Master Plan'!A28 -> 22 | B26: ='Master Plan'!C25 -> Chuyển giao cho đội phát triển (Transfer) | C26: ='Master Plan'!D28 -> Ước lượng effort & xác định velocity dự kiến | D26: ='Master Plan'!G28 -> 46264 | E26: ='Master Plan'!H28 -> 46265 | F26: =E26-D26+1 -> 2 | G26: ='Master Plan'!N28/100 -> 0 | H26: =ROUND(F26*G26,2) -> 0 | I26: =F26-H26 -> 2
A27: ='Master Plan'!A29 -> 23 | B27: ='Master Plan'!C29 -> Phát triển - Sprint 0 (Chuẩn bị) | C27: ='Master Plan'!D29 -> Setup hạ tầng, Design System, Authentication & phân quyền cơ bản | D27: ='Master Plan'!G29 -> 46266 | E27: ='Master Plan'!H29 -> 46272 | F27: =E27-D27+1 -> 7 | G27: ='Master Plan'!N29/100 -> 0 | H27: =ROUND(F27*G27,2) -> 0 | I27: =F27-H27 -> 7
A28: ='Master Plan'!A30 -> 24 | B28: ='Master Plan'!C29 -> Phát triển - Sprint 0 (Chuẩn bị) | C28: ='Master Plan'!D30 -> App: Đặt lịch bảo hành/bảo dưỡng | Web: Tiếp nhận đơn (từ App + walk-in) | D28: ='Master Plan'!G30 -> 46273 | E28: ='Master Plan'!H30 -> 46286 | F28: =E28-D28+1 -> 14 | G28: ='Master Plan'!N30/100 -> 0 | H28: =ROUND(F28*G28,2) -> 0 | I28: =F28-H28 -> 14
A29: ='Master Plan'!A31 -> 25 | B29: ='Master Plan'!C29 -> Phát triển - Sprint 0 (Chuẩn bị) | C29: ='Master Plan'!D31 -> Web: Kỹ thuật đánh giá phương án sửa chữa & lập báo giá | App: Khách hàng xem báo giá, xác nhận & thanh toán (online / tiền mặt) | D29: ='Master Plan'!G31 -> 46287 | E29: ='Master Plan'!H31 -> 46300 | F29: =E29-D29+1 -> 14 | G29: ='Master Plan'!N31/100 -> 0 | H29: =ROUND(F29*G29,2) -> 0 | I29: =F29-H29 -> 14
A30: ='Master Plan'!A32 -> 26 | B30: ='Master Plan'!C29 -> Phát triển - Sprint 0 (Chuẩn bị) | C30: ='Master Plan'!D32 -> Web: Điều phối thợ theo khu vực/lịch rảnh, hồ sơ & chấm công thợ | App: Hiển thị trạng thái đơn real-time | D30: ='Master Plan'!G32 -> 46301 | E30: ='Master Plan'!H32 -> 46314 | F30: =E30-D30+1 -> 14 | G30: ='Master Plan'!N32/100 -> 0 | H30: =ROUND(F30*G30,2) -> 0 | I30: =F30-H30 -> 14
A31: ='Master Plan'!A33 -> 27 | B31: ='Master Plan'!C29 -> Phát triển - Sprint 0 (Chuẩn bị) | C31: ='Master Plan'!D33 -> App: Theo dõi tiến độ chi tiết, lịch sử dịch vụ, thông báo | Web: Nhật ký xử lý đơn & hồ sơ khách hàng (CRM) | D31: ='Master Plan'!G33 -> 46315 | E31: ='Master Plan'!H33 -> 46328 | F31: =E31-D31+1 -> 14 | G31: ='Master Plan'!N33/100 -> 0 | H31: =ROUND(F31*G31,2) -> 0 | I31: =F31-H31 -> 14
A32: ='Master Plan'!A34 -> 28 | B32: ='Master Plan'!C29 -> Phát triển - Sprint 0 (Chuẩn bị) | C32: ='Master Plan'!D34 -> Web: Quản lý kho linh kiện (danh mục, tồn kho, nhập kho, cảnh báo tồn thấp) | D32: ='Master Plan'!G34 -> 46329 | E32: ='Master Plan'!H34 -> 46342 | F32: =E32-D32+1 -> 14 | G32: ='Master Plan'!N34/100 -> 0 | H32: =ROUND(F32*G32,2) -> 0 | I32: =F32-H32 -> 14
A33: ='Master Plan'!A35 -> 29 | B33: ='Master Plan'!C29 -> Phát triển - Sprint 0 (Chuẩn bị) | C33: ='Master Plan'!D35 -> Web: Cấp phát linh kiện cho thợ, đối soát | App: Xem chi tiết linh kiện & chi phí | D33: ='Master Plan'!G35 -> 46343 | E33: ='Master Plan'!H35 -> 46356 | F33: =E33-D33+1 -> 14 | G33: ='Master Plan'!N35/100 -> 0 | H33: =ROUND(F33*G33,2) -> 0 | I33: =F33-H33 -> 14
A34: ='Master Plan'!A36 -> 30 | B34: ='Master Plan'!C29 -> Phát triển - Sprint 0 (Chuẩn bị) | C34: ='Master Plan'!D36 -> App: Đánh giá dịch vụ | Web: Dashboard báo cáo, quản trị người dùng/phân quyền, nhật ký hoạt động (audit log), KPI thợ | D34: ='Master Plan'!G36 -> 46357 | E34: ='Master Plan'!H36 -> 46370 | F34: =E34-D34+1 -> 14 | G34: ='Master Plan'!N36/100 -> 0 | H34: =ROUND(F34*G34,2) -> 0 | I34: =F34-H34 -> 14
A35: ='Master Plan'!A37 -> 31 | B35: ='Master Plan'!C29 -> Phát triển - Sprint 0 (Chuẩn bị) | C35: ='Master Plan'!D37 -> Tối ưu hiệu năng, hoàn thiện UX, rà soát bảo mật, fix bug tồn đọng | D35: ='Master Plan'!G37 -> 46371 | E35: ='Master Plan'!H37 -> 46384 | F35: =E35-D35+1 -> 14 | G35: ='Master Plan'!N37/100 -> 0 | H35: =ROUND(F35*G35,2) -> 0 | I35: =F35-H35 -> 14
A36: ='Master Plan'!A38 -> 32 | B36: ='Master Plan'!C38 -> Kiểm thử hệ thống (SIT/UAT) | C36: ='Master Plan'!D38 -> SIT - Kiểm thử tích hợp App ↔ Backend ↔ Web | D36: ='Master Plan'!G38 -> 46385 | E36: ='Master Plan'!H38 -> 46390 | F36: =E36-D36+1 -> 6 | G36: ='Master Plan'!N38/100 -> 0 | H36: =ROUND(F36*G36,2) -> 0 | I36: =F36-H36 -> 6
A37: ='Master Plan'!A39 -> 33 | B37: ='Master Plan'!C38 -> Kiểm thử hệ thống (SIT/UAT) | C37: ='Master Plan'!D39 -> UAT - Người dùng thực tế thử nghiệm theo kịch bản | D37: ='Master Plan'!G39 -> 46391 | E37: ='Master Plan'!H39 -> 46394 | F37: =E37-D37+1 -> 4 | G37: ='Master Plan'!N39/100 -> 0 | H37: =ROUND(F37*G37,2) -> 0 | I37: =F37-H37 -> 4
A38: ='Master Plan'!A40 -> 34 | B38: ='Master Plan'!C38 -> Kiểm thử hệ thống (SIT/UAT) | C38: ='Master Plan'!D40 -> Fix lỗi & retest theo mức độ ưu tiên | D38: ='Master Plan'!G40 -> 46393 | E38: ='Master Plan'!H40 -> 46397 | F38: =E38-D38+1 -> 5 | G38: ='Master Plan'!N40/100 -> 0 | H38: =ROUND(F38*G38,2) -> 0 | I38: =F38-H38 -> 5
A39: ='Master Plan'!A41 -> 35 | B39: ='Master Plan'!C38 -> Kiểm thử hệ thống (SIT/UAT) | C39: ='Master Plan'!D41 -> Xác nhận UAT Pass từ khách hàng | D39: ='Master Plan'!G41 -> 46398 | E39: ='Master Plan'!H41 -> 46398 | F39: =E39-D39+1 -> 1 | G39: ='Master Plan'!N41/100 -> 0 | H39: =ROUND(F39*G39,2) -> 0 | I39: =F39-H39 -> 1
A40: ='Master Plan'!A42 -> 36 | B40: ='Master Plan'!C42 -> Bàn giao & Nghiệm thu | C40: ='Master Plan'!D42 -> Triển khai lên môi trường Production (App Store/CH Play, Web hosting) | D40: ='Master Plan'!G42 -> 46399 | E40: ='Master Plan'!H42 -> 46400 | F40: =E40-D40+1 -> 2 | G40: ='Master Plan'!N42/100 -> 0 | H40: =ROUND(F40*G40,2) -> 0 | I40: =F40-H40 -> 2
A41: ='Master Plan'!A43 -> 37 | B41: ='Master Plan'!C42 -> Bàn giao & Nghiệm thu | C41: ='Master Plan'!D43 -> Đào tạo người dùng cho nhân viên Trung tâm ABC | D41: ='Master Plan'!G43 -> 46400 | E41: ='Master Plan'!H43 -> 46401 | F41: =E41-D41+1 -> 2 | G41: ='Master Plan'!N43/100 -> 0 | H41: =ROUND(F41*G41,2) -> 0 | I41: =F41-H41 -> 2
...
