Workbook

Sheet Tổng quan
A1: MASTER PLAN DỰ ÁN HẢI ANH HOMECARE
A4: Tên dự án: Hệ thống Điện máy Hải Anh
A5: Loại hình: Web App + Mobile App (Khách hàng / Kỹ thuật viên / Quản trị)
A6: Phương pháp triển khai: Waterfall (Khảo sát-Thiết kế-Tài liệu-Chuyển giao) kết hợp Agile Scrum (giai đoạn Phát triển)
A7: BA phụ trách: Thiều Thị Thúy
A8: PM phụ trách: Nguyễn Văn Đức
A11: Ngày bắt đầu dự án (Input) | C11: 46237
A12: Ngày kết thúc dự kiến (tự động) | C12: =MAX('Master Plan'!F6:Z49) -> 46423
A13: Tổng số ngày dự án (lịch) | C13: =C12-C11+1 -> 187
A15: TỔNG QUAN CÁC GIAI ĐOẠN DỰ ÁN
A16: # | B16: Giai đoạn | C16: Số ngày (lịch) | D16: Bắt đầu | E16: Kết thúc | F16: Tỷ trọng
A17: 1 | B17: 1. KHỞI TẠO & KHẢO SÁT | C17: =SUM('Master Plan'!E6:E8) -> 13 | D17: =MIN('Master Plan'!D6:D8) -> 46237 | E17: =MAX('Master Plan'!F6:F8) -> 46249 | F17: =C17/$C$13 -> 0.069518717
A18: 2 | B18: 2. PHÂN TÍCH & THIẾT KẾ | C18: =SUM('Master Plan'!E10:E13) -> 21 | D18: =MIN('Master Plan'!D10:D13) -> 46250 | E18: =MAX('Master Plan'!F10:F13) -> 46270 | F18: =C18/$C$13 -> 0.11229947
A19: 3 | B19: 3. LẬP TÀI LIỆU | C19: =SUM('Master Plan'!E15:E17) -> 11 | D19: =MIN('Master Plan'!D15:D17) -> 46271 | E19: =MAX('Master Plan'!F15:F17) -> 46281 | F19: =C19/$C$13 -> 0.058823529
A20: 4 | B20: 4. XÁC NHẬN TÀI LIỆU | C20: =SUM('Master Plan'!E19:E21) -> 7 | D20: =MIN('Master Plan'!D19:D21) -> 46282 | E20: =MAX('Master Plan'!F19:F21) -> 46288 | F20: =C20/$C$13 -> 0.037433155
A21: 5 | B21: 5. KICKOFF DỰ ÁN PHÁT TRIỂN | C21: =SUM('Master Plan'!E23:E24) -> 3 | D21: =MIN('Master Plan'!D23:D24) -> 46289 | E21: =MAX('Master Plan'!F23:F24) -> 46291 | F21: =C21/$C$13 -> 0.016042781
A22: 6 | B22: 6. CHUYỂN GIAO (TRANSFER) | C22: =SUM('Master Plan'!E26:E27) -> 4 | D22: =MIN('Master Plan'!D26:D27) -> 46292 | E22: =MAX('Master Plan'!F26:F27) -> 46295 | F22: =C22/$C$13 -> 0.021390374
A23: 7 | B23: 7. PHÁT TRIỂN HỆ THỐNG (AGILE - XEM SHEET SPRINT PLAN) | C23: =SUM('Master Plan'!E29:E36) -> 75 | D23: =MIN('Master Plan'!D29:D36) -> 46296 | E23: =MAX('Master Plan'!F29:F36) -> 46370 | F23: =C23/$C$13 -> 0.40106952
A24: 8 | B24: 8. KIỂM THỬ TỔNG THỂ (SIT/UAT) | C24: =SUM('Master Plan'!E38:E40) -> 13 | D24: =MIN('Master Plan'!D38:D40) -> 46371 | E24: =MAX('Master Plan'!F38:F40) -> 46383 | F24: =C24/$C$13 -> 0.069518717
A25: 9 | B25: 9. BÀN GIAO (HANDOVER) | C25: =SUM('Master Plan'!E42:E44) -> 6 | D25: =MIN('Master Plan'!D42:D44) -> 46384 | E25: =MAX('Master Plan'!F42:F44) -> 46389 | F25: =C25/$C$13 -> 0.032085561
A26: 10 | B26: 10. NGHIỆM THU (ACCEPTANCE) | C26: =SUM('Master Plan'!E46:E47) -> 4 | D26: =MIN('Master Plan'!D46:D47) -> 46390 | E26: =MAX('Master Plan'!F46:F47) -> 46393 | F26: =C26/$C$13 -> 0.021390374
A27: 11 | B27: 11. BẢO HÀNH & HỖ TRỢ SAU DỰ ÁN | C27: =SUM('Master Plan'!E49) -> 30 | D27: =MIN('Master Plan'!D49) -> 46394 | E27: =MAX('Master Plan'!F49) -> 46423 | F27: =C27/$C$13 -> 0.16042781
A29: Ghi chú: Đổi ô B11 (ngày bắt đầu) sẽ tự động cập nhật toàn bộ lịch trình ở sheet 'Master Plan' và 'Sprint Plan'. Số ngày ở cột 'Số ngày (lịch)' của Master Plan là ô nhập liệu (màu vàng) — có thể điều chỉnh theo thực tế.

Sheet Master Plan
A1: MASTER PLAN — DỰ ÁN HỆ THỐNG ĐẶT LỊCH HẸN & QUẢN LÝ SỬA CHỮA ĐIỆN TỬ - ĐIỆN LẠNH
A2: Ngày bắt đầu dự án (liên kết từ sheet Tổng quan): | D2: ='Tổng quan'!$C$11 -> 46237
A4: STT | B4: Giai đoạn | C4: Hạng mục công việc | D4: Ngày bắt đầu | E4: Số ngày (lịch) | F4: Ngày kết thúc | G4: Phụ trách | H4: Kết quả bàn giao | I4: Trạng thái | J4: % Hoàn thành | K4: Ghi chú | L4: =D2 -> 46237 | M4: =L4+7 -> 46244 | N4: =M4+7 -> 46251 | O4: =N4+7 -> 46258 | P4: =O4+7 -> 46265 | Q4: =P4+7 -> 46272 | R4: =Q4+7 -> 46279 | S4: =R4+7 -> 46286 | T4: =S4+7 -> 46293 | ... AI4: =AH4+7 -> 46398
B5: 1. KHỞI TẠO & KHẢO SÁT
A6: 1 | C6: Thu thập yêu cầu ban đầu từ khách hàng | D6: =D2 -> 46237 | E6: 5 | F6: =D6+E6-1 -> 46241 | G6: BA | H6: Biên bản họp yêu cầu | I6: Chưa bắt đầu | J6: 0
A7: 2 | C7: Khảo sát hiện trạng & quy trình vận hành sửa chữa | D7: =F6+1 -> 46242 | E7: 5 | F7: =D7+E7-1 -> 46246 | G7: BA | H7: Báo cáo khảo sát hiện trạng | I7: Chưa bắt đầu | J7: 0
A8: 3 | C8: Lập báo cáo khảo sát tổng hợp | D8: =F7+1 -> 46247 | E8: 3 | F8: =D8+E8-1 -> 46249 | G8: BA | H8: Báo cáo khảo sát (Survey Report) | I8: Chưa bắt đầu | J8: 0
B9: 2. PHÂN TÍCH & THIẾT KẾ
A10: 4 | C10: Phân tích nghiệp vụ, xây dựng BRD | D10: =F8+1 -> 46250 | E10: 5 | F10: =D10+E10-1 -> 46254 | G10: BA | H10: BRD | I10: Chưa bắt đầu | J10: 0
A11: 5 | C11: Thiết kế UI/UX (wireframe, mockup) | D11: =F10+1 -> 46255 | E11: 7 | F11: =D11+E11-1 -> 46261 | G11: UI/UX Designer | H11: Wireframe & Mockup | I11: Chưa bắt đầu | J11: 0
A12: 6 | C12: Thiết kế kiến trúc hệ thống & CSDL | D12: =F11+1 -> 46262 | E12: 5 | F12: =D12+E12-1 -> 46266 | G12: Kiến trúc sư (SA) | H12: Tài liệu kiến trúc & DB Design | I12: Chưa bắt đầu | J12: 0
A13: 7 | C13: Thiết kế API & tích hợp (thanh toán, SMS/notification) | D13: =F12+1 -> 46267 | E13: 4 | F13: =D13+E13-1 -> 46270 | G13: Kiến trúc sư (SA) | H13: Tài liệu đặc tả API | I13: Chưa bắt đầu | J13: 0
B14: 3. LẬP TÀI LIỆU
A15: 8 | C15: Soạn thảo SRS (Software Requirement Spec) | D15: =F13+1 -> 46271 | E15: 4 | F15: =D15+E15-1 -> 46274 | G15: BA | H15: SRS | I15: Chưa bắt đầu | J15: 0
A16: 9 | C16: Soạn thảo tài liệu thiết kế kỹ thuật (TDD) | D16: =F15+1 -> 46275 | E16: 4 | F16: =D16+E16-1 -> 46278 | G16: SA/Dev Lead | H16: Technical Design Document | I16: Chưa bắt đầu | J16: 0
A17: 10 | C17: Soạn thảo Test Plan & Test Case tổng thể | D17: =F16+1 -> 46279 | E17: 3 | F17: =D17+E17-1 -> 46281 | G17: QA Lead | H17: Test Plan tổng thể | I17: Chưa bắt đầu | J17: 0
B18: 4. XÁC NHẬN TÀI LIỆU
A19: 11 | C19: Gửi tài liệu cho khách hàng review | D19: =F17+1 -> 46282 | E19: 2 | F19: =D19+E19-1 -> 46283 | G19: BA | H19: Email/Biên bản gửi tài liệu | I19: Chưa bắt đầu | J19: 0
A20: 12 | C20: Họp giải trình & chỉnh sửa theo góp ý | D20: =F19+1 -> 46284 | E20: 3 | F20: =D20+E20-1 -> 46286 | G20: BA/SA | H20: Biên bản họp góp ý | I20: Chưa bắt đầu | J20: 0
A21: 13 | C21: Khách hàng ký duyệt (sign-off) tài liệu | D21: =F20+1 -> 46287 | E21: 2 | F21: =D21+E21-1 -> 46288 | G21: Khách hàng/PM | H21: Biên bản xác nhận tài liệu | I21: Chưa bắt đầu | J21: 0
B22: 5. KICKOFF DỰ ÁN PHÁT TRIỂN
A23: 14 | C23: Họp kickoff với đội phát triển | D23: =F21+1 -> 46289 | E23: 1 | F23: =D23+E23-1 -> 46289 | G23: PM | H23: Biên bản kickoff | I23: Chưa bắt đầu | J23: 0
A24: 15 | C24: Phân công vai trò & thiết lập công cụ quản lý (Jira/Confluence) | D24: =F23+1 -> 46290 | E24: 2 | F24: =D24+E24-1 -> 46291 | G24: PM | H24: Cấu hình công cụ dự án | I24: Chưa bắt đầu | J24: 0
B25: 6. CHUYỂN GIAO (TRANSFER)
A26: 16 | C26: Chuyển giao tài liệu & yêu cầu cho đội Dev/QA | D26: =F24+1 -> 46292 | E26: 2 | F26: =D26+E26-1 -> 46293 | G26: BA/PM | H26: Biên bản chuyển giao | I26: Chưa bắt đầu | J26: 0
A27: 17 | C27: Đào tạo nội bộ về nghiệp vụ cho Dev/QA | D27: =F26+1 -> 46294 | E27: 2 | F27: =D27+E27-1 -> 46295 | G27: BA | H27: Slide đào tạo nội bộ | I27: Chưa bắt đầu | J27: 0
B28: 7. PHÁT TRIỂN HỆ THỐNG (AGILE - XEM SHEET SPRINT PLAN)
A29: 18 | C29: Sprint 0 - Chuẩn bị môi trường & Backlog | D29: =F27+1 -> 46296 | E29: 5 | F29: =D29+E29-1 -> 46300 | G29: Dev Team/PM | H29: Môi trường Dev/Test, Product Backlog | I29: Chưa bắt đầu | J29: 0
A30: 19 | C30: Sprint 1 - Quản lý người dùng & phân quyền | D30: =F29+1 -> 46301 | E30: 10 | F30: =D30+E30-1 -> 46310 | G30: Dev Team | H30: Module User & phân quyền | I30: Chưa bắt đầu | J30: 0
A31: 20 | C31: Sprint 2 - Đặt lịch hẹn (Booking) | D31: =F30+1 -> 46311 | E31: 10 | F31: =D31+E31-1 -> 46320 | G31: Dev Team | H31: Module đặt lịch hẹn | I31: Chưa bắt đầu | J31: 0
A32: 21 | C32: Sprint 3 - Quản lý kỹ thuật viên & phân công | D32: =F31+1 -> 46321 | E32: 10 | F32: =D32+E32-1 -> 46330 | G32: Dev Team | H32: Module quản lý KTV & phân công | I32: Chưa bắt đầu | J32: 0
A33: 22 | C33: Sprint 4 - Quản lý sửa chữa (tiếp nhận-tình trạng-linh kiện) | D33: =F32+1 -> 46331 | E33: 10 | F33: =D33+E33-1 -> 46340 | G33: Dev Team | H33: Module quản lý sửa chữa | I33: Chưa bắt đầu | J33: 0
A34: 23 | C34: Sprint 5 - Thanh toán & hóa đơn điện tử | D34: =F33+1 -> 46341 | E34: 10 | F34: =D34+E34-1 -> 46350 | G34: Dev Team | H34: Module thanh toán & hóa đơn | I34: Chưa bắt đầu | J34: 0
A35: 24 | C35: Sprint 6 - Báo cáo, thống kê & thông báo (notification) | D35: =F34+1 -> 46351 | E35: 10 | F35: =D35+E35-1 -> 46360 | G35: Dev Team | H35: Module báo cáo & notification | I35: Chưa bắt đầu | J35: 0
A36: 25 | C36: Sprint 7 - Hoàn thiện, sửa lỗi & tối ưu (bug fixing, polish) | D36: =F35+1 -> 46361 | E36: 10 | F36: =D36+E36-1 -> 46370 | G36: Dev Team | H36: Build hoàn chỉnh (Release Candidate) | I36: Chưa bắt đầu | J36: 0
B37: 8. KIỂM THỬ TỔNG THỂ (SIT/UAT)
A38: 26 | C38: Kiểm thử tích hợp hệ thống (SIT) | D38: =F36+1 -> 46371 | E38: 5 | F38: =D38+E38-1 -> 46375 | G38: QA Team | H38: Báo cáo SIT | I38: Chưa bắt đầu | J38: 0
A39: 27 | C39: Kiểm thử chấp nhận người dùng (UAT) cùng khách hàng | D39: =F38+1 -> 46376 | E39: 5 | F39: =D39+E39-1 -> 46380 | G39: QA/Khách hàng | H39: Báo cáo UAT | I39: Chưa bắt đầu | J39: 0
A40: 28 | C40: Sửa lỗi sau UAT | D40: =F39+1 -> 46381 | E40: 3 | F40: =D40+E40-1 -> 46383 | G40: Dev Team | H40: Build đã sửa lỗi UAT | I40: Chưa bắt đầu | J40: 0
B41: 9. BÀN GIAO (HANDOVER)
...

Sheet Sprint Plan
A1: SPRINT PLAN (AGILE SCRUM) — GIAI ĐOẠN PHÁT TRIỂN HỆ THỐNG
A2: Ghi chú: Ngày bắt đầu/kết thúc và Số ngày của từng Sprint được liên kết trực tiếp từ sheet 'Master Plan' (mục 7 - Phát triển hệ thống) để đảm bảo tính nhất quán.
A4: Sprint | B4: Mục tiêu Sprint / Chức năng chính | C4: Ngày bắt đầu | D4: Số ngày | E4: Ngày kết thúc | F4: Story Points (ước lượng) | G4: Đội thực hiện | H4: Trạng thái | I4: Ghi chú
A5: Sprint 0 | B5: Chuẩn bị môi trường Dev/Test/CI-CD & hoàn thiện Product Backlog | C5: ='Master Plan'!D29 -> 46296 | D5: ='Master Plan'!E29 -> 5 | E5: ='Master Plan'!F29 -> 46300 | F5: 8 | G5: Dev Team/PM | H5: Chưa bắt đầu
A6: Sprint 1 | B6: Quản lý người dùng & phân quyền (Admin/Tổng đài/KTV/Khách hàng) | C6: ='Master Plan'!D30 -> 46301 | D6: ='Master Plan'!E30 -> 10 | E6: ='Master Plan'!F30 -> 46310 | F6: 21 | G6: Dev Team | H6: Chưa bắt đầu
A7: Sprint 2 | B7: Đặt lịch hẹn (Booking): chọn dịch vụ, khung giờ, xác nhận/hủy/đổi lịch | C7: ='Master Plan'!D31 -> 46311 | D7: ='Master Plan'!E31 -> 10 | E7: ='Master Plan'!F31 -> 46320 | F7: 21 | G7: Dev Team | H7: Chưa bắt đầu
A8: Sprint 3 | B8: Quản lý kỹ thuật viên & phân công lịch hẹn theo khu vực | C8: ='Master Plan'!D32 -> 46321 | D8: ='Master Plan'!E32 -> 10 | E8: ='Master Plan'!F32 -> 46330 | F8: 23 | G8: Dev Team | H8: Chưa bắt đầu
A9: Sprint 4 | B9: Quản lý sửa chữa: tiếp nhận thiết bị, tiến độ, kho linh kiện, báo giá | C9: ='Master Plan'!D33 -> 46331 | D9: ='Master Plan'!E33 -> 10 | E9: ='Master Plan'!F33 -> 46340 | F9: 29 | G9: Dev Team | H9: Chưa bắt đầu
A10: Sprint 5 | B10: Thanh toán & hóa đơn điện tử, tích hợp cổng thanh toán | C10: ='Master Plan'!D34 -> 46341 | D10: ='Master Plan'!E34 -> 10 | E10: ='Master Plan'!F34 -> 46350 | F10: 23 | G10: Dev Team | H10: Chưa bắt đầu
A11: Sprint 6 | B11: Báo cáo, thống kê, đánh giá khách hàng & thông báo đa kênh | C11: ='Master Plan'!D35 -> 46351 | D11: ='Master Plan'!E35 -> 10 | E11: ='Master Plan'!F35 -> 46360 | F11: 21 | G11: Dev Team | H11: Chưa bắt đầu
A12: Sprint 7 | B12: Hoàn thiện, sửa lỗi nội bộ, tối ưu hiệu năng & bảo mật | C12: ='Master Plan'!D36 -> 46361 | D12: ='Master Plan'!E36 -> 10 | E12: ='Master Plan'!F36 -> 46370 | F12: 21 | G12: Dev Team | H12: Chưa bắt đầu
A14: CHI TIẾT BACKLOG THEO SPRINT (USER STORIES)
A15: Sprint | B15: Mã US | C15: User Story | D15: Độ ưu tiên | E15: Story Points | F15: Vai trò phụ trách | G15: Trạng thái
A16: Sprint 0 | B16: US-000 | C16: Thiết lập môi trường Dev/Test & CI-CD cơ bản | D16: Cao | E16: 5 | F16: DevOps | G16: Chưa bắt đầu
A17: Sprint 0 | B17: US-001 | C17: Chuẩn hóa Product Backlog & Definition of Done | D17: Cao | E17: 3 | F17: PM/BA | G17: Chưa bắt đầu
A18: Sprint 1 | B18: US-101 | C18: Đăng ký tài khoản khách hàng (email/SĐT/OTP) | D18: Cao | E18: 5 | F18: Dev Team | G18: Chưa bắt đầu
A19: Sprint 1 | B19: US-102 | C19: Đăng nhập / Quên mật khẩu | D19: Cao | E19: 3 | F19: Dev Team | G19: Chưa bắt đầu
A20: Sprint 1 | B20: US-103 | C20: Phân quyền Admin - Tổng đài - Kỹ thuật viên - Khách hàng | D20: Cao | E20: 8 | F20: Dev Team | G20: Chưa bắt đầu
A21: Sprint 1 | B21: US-104 | C21: Quản lý hồ sơ khách hàng & lịch sử thiết bị đã sửa | D21: Trung bình | E21: 5 | F21: Dev Team | G21: Chưa bắt đầu
A22: Sprint 2 | B22: US-201 | C22: Khách hàng chọn dịch vụ & loại thiết bị (điện tử/điện lạnh) | D22: Cao | E22: 5 | F22: Dev Team | G22: Chưa bắt đầu
A23: Sprint 2 | B23: US-202 | C23: Chọn khung giờ hẹn theo lịch trống của khu vực | D23: Cao | E23: 8 | F23: Dev Team | G23: Chưa bắt đầu
A24: Sprint 2 | B24: US-203 | C24: Xác nhận / Hủy / Đổi lịch hẹn | D24: Cao | E24: 5 | F24: Dev Team | G24: Chưa bắt đầu
A25: Sprint 2 | B25: US-204 | C25: Nhắc lịch hẹn qua SMS/Push notification | D25: Trung bình | E25: 3 | F25: Dev Team | G25: Chưa bắt đầu
A26: Sprint 3 | B26: US-301 | C26: Quản lý danh sách kỹ thuật viên & khu vực phụ trách | D26: Cao | E26: 5 | F26: Dev Team | G26: Chưa bắt đầu
A27: Sprint 3 | B27: US-302 | C27: Tự động phân công kỹ thuật viên theo lịch hẹn & khu vực | D27: Cao | E27: 8 | F27: Dev Team | G27: Chưa bắt đầu
... A44: Sprint 7 | B44: US-703 | C44: Chuẩn bị dữ liệu demo & môi trường cho UAT | D44: Cao | E44: 5 | F44: Dev Team | G44: Chưa bắt đầu
A46: Tổng Story Points toàn dự án (SUM cột Story Points của backlog): | G46: =SUM(E16:E44) -> 167

Sheet Tài liệu dự án
A1: DANH SÁCH TÀI LIỆU DỰ ÁN & TRẠNG THÁI XÁC NHẬN (SIGN-OFF)
A3: Mã TL | B3: Tên tài liệu | C3: Giai đoạn liên quan | D3: Người phụ trách | E3: Ngày hoàn thành dự kiến | F3: Trạng thái | G3: Ngày xác nhận (Sign-off) | H3: Người xác nhận | I3: Phiên bản | J3: Ghi chú
A4: TL-01 | B4: Báo cáo khảo sát hiện trạng (Survey Report) | C4: 1. Khởi tạo & Khảo sát | D4: BA | F4: Chưa bắt đầu | I4: v1.0
A5: TL-02 | B5: BRD - Business Requirement Document | C5: 2. Phân tích & Thiết kế | D5: BA | F5: Chưa bắt đầu | I5: v1.0
A6: TL-03 | B6: Wireframe / Mockup UI-UX | C6: 2. Phân tích & Thiết kế | D6: UI/UX Designer | F6: Chưa bắt đầu | I6: v1.0
A7: TL-04 | B7: Tài liệu kiến trúc hệ thống & thiết kế CSDL | C7: 2. Phân tích & Thiết kế | D7: Kiến trúc sư (SA) | F7: Chưa bắt đầu | I7: v1.0
A8: TL-05 | B8: Tài liệu đặc tả API (API Specification) | C8: 2. Phân tích & Thiết kế | D8: Kiến trúc sư (SA) | F8: Chưa bắt đầu | I8: v1.0
A9: TL-06 | B9: SRS - Software Requirement Specification | C9: 3. Lập tài liệu | D9: BA | F9: Chưa bắt đầu | I9: v1.0
A10: TL-07 | B10: TDD - Technical Design Document | C10: 3. Lập tài liệu | D10: SA/Dev Lead | F10: Chưa bắt đầu | I10: v1.0
A11: TL-08 | B11: Test Plan & Test Case tổng thể | C11: 3. Lập tài liệu | D11: QA Lead | F11: Chưa bắt đầu | I11: v1.0
A12: TL-09 | B12: Biên bản xác nhận tài liệu (Sign-off) | C12: 4. Xác nhận tài liệu | D12: Khách hàng/PM | F12: Chưa bắt đầu | I12: v1.0
A13: TL-10 | B13: Biên bản kickoff dự án phát triển | C13: 5. Kickoff dự án phát triển | D13: PM | F13: Chưa bắt đầu | I13: v1.0
A14: TL-11 | B14: Biên bản chuyển giao tài liệu cho Dev/QA | C14: 6. Chuyển giao (Transfer) | D14: BA/PM | F14: Chưa bắt đầu | I14: v1.0
A15: TL-12 | B15: Báo cáo kiểm thử tích hợp hệ thống (SIT) | C15: 8. Kiểm thử tổng thể | D15: QA Team | F15: Chưa bắt đầu | I15: v1.0
... A21: TL-18 | B21: Cam kết/Hợp đồng bảo hành & hỗ trợ sau bàn giao | C21: 11. Bảo hành & hỗ trợ | D21: PM | F21: Chưa bắt đầu | I21: v1.0

Sheet Bàn giao-Nghiệm thu
A1: CHECKLIST BÀN GIAO & NGHIỆM THU DỰ ÁN
A3: # | B3: Hạng mục bàn giao | C3: Mô tả chi tiết | D3: Điều kiện nghiệm thu (Acceptance Criteria) | E3: Người phụ trách bàn giao | F3: Người nghiệm thu (Khách hàng) | G3: Trạng thái | H3: Ngày ký xác nhận
A4: 1 | B4: Mã nguồn hệ thống (Source Code) | C4: Toàn bộ source code Frontend/Backend, có quản lý phiên bản (Git) | D4: Source code chạy được, có tài liệu README, bàn giao qua Git repository | E4: PM/Dev Team | F4: Khách hàng | G4: Chưa thực hiện
A5: 2 | B5: Tài liệu kỹ thuật & vận hành | C5: TDD, API Spec, Deployment Guide, sơ đồ CSDL | D5: Đầy đủ tài liệu, khớp với hệ thống thực tế đã triển khai | E5: SA/Dev Lead | F5: Khách hàng | G5: Chưa thực hiện
A6: 3 | B6: Tài khoản quản trị hệ thống | C6: Tài khoản Admin, tài khoản hạ tầng/server, tài khoản dịch vụ bên thứ 3 | D6: Bàn giao đầy đủ, đổi mật khẩu mặc định, có hướng dẫn phân quyền | E6: DevOps/PM | F6: Khách hàng | G6: Chưa thực hiện
A7: 4 | B7: Môi trường Production | C7: Hệ thống đã triển khai & vận hành ổn định trên môi trường thật | D7: Hệ thống hoạt động đúng chức năng, không lỗi nghiêm trọng (Critical/Major) | E7: DevOps/Dev Team | F7: QA/Khách hàng | G7: Chưa thực hiện
A8: 5 | B8: Đào tạo người dùng cuối | C8: Đào tạo trực tiếp/online cho nhân viên tổng đài, kỹ thuật viên, quản trị viên | D8: Người dùng thao tác thành thạo các chức năng chính sau đào tạo | E8: BA/Dev Team | F8: Khách hàng | G8: Chưa thực hiện
A9: 6 | B9: User Manual & tài liệu hướng dẫn | C9: Tài liệu hướng dẫn sử dụng cho từng vai trò người dùng | D9: Tài liệu rõ ràng, đầy đủ, dễ hiểu, có hình ảnh minh họa | E9: BA | F9: Khách hàng | G9: Chưa thực hiện
A10: 7 | B10: Bảo hành hệ thống | C10: Cam kết bảo hành & hỗ trợ kỹ thuật sau bàn giao (thời hạn theo hợp đồng) | D10: Có văn bản/hợp đồng bảo hành, kênh hỗ trợ (hotline/email) rõ ràng | E10: PM | F10: Khách hàng | G10: Chưa thực hiện
A11: 8 | B11: Biên bản nghiệm thu tổng thể | C11: Biên bản xác nhận hoàn thành & nghiệm thu toàn bộ dự án | D11: Hai bên ký xác nhận, không còn lỗi Critical/Major tồn đọng | E11: PM | F11: Khách hàng | G11: Chưa thực hiện
A14: Đại diện Bên Giao (Đơn vị phát triển) | E14: Đại diện Bên Nhận (Khách hàng)
A15: (Ký, ghi rõ họ tên) | E15: (Ký, ghi rõ họ tên)
