Workbook

Sheet Tổng quan
A1: TỔNG QUAN TIẾN ĐỘ DỰ ÁN — MASTER PLAN THỎ XING
A2: Toàn bộ số liệu bên dưới được tính tự động từ sheet "Master Plan" — chỉ cần cập nhật Trạng thái ở đó, bảng này sẽ tự làm mới.
A4: TỔNG SỐ HẠNG MỤC | C4: ĐÃ HOÀN THÀNH | E4: ĐANG THỰC HIỆN | G4: CHƯA BẮT ĐẦU
A5: =COUNT('Master Plan'!A5:A34) -> 30 | C5: =COUNTIF('Master Plan'!J5:J34,"Hoàn thành") -> 0 | E5: =COUNTIF('Master Plan'!J5:J34,"Đang thực hiện") -> 0 | G5: =COUNTIF('Master Plan'!J5:J34,"Chưa bắt đầu") -> 30
A8: % HOÀN THÀNH TỔNG THỂ | C8: TRỄ HẠN (TỰ ĐỘNG PHÁT HIỆN) | E8: THỜI GIAN DỰ ÁN (TUẦN) | G8: TRỄ TIẾN ĐỘ (THỦ CÔNG)
A9: =COUNTIF('Master Plan'!J5:J34,"Hoàn thành")/COUNT('Master Plan'!A5:A34) -> 0 | C9: =COUNTIFS('Master Plan'!H5:H34,"<"&TODAY(),'Master Plan'!J5:J34,"<>Hoàn thành") -> 0 | E9: =(MAX('Master Plan'!H5:H34)-MIN('Master Plan'!G5:G34)+1)/7 -> 21.571429 | G9: =COUNTIF('Master Plan'!J5:J34,"Trễ tiến độ") -> 0
A11: Ngày bắt đầu dự án: | E11: =MIN('Master Plan'!G5:G34) -> 46237
A12: Ngày kết thúc dự kiến (chưa gồm bảo hành): | E12: =MAX('Master Plan'!H5:H34) -> 46387
A15: TIẾN ĐỘ THEO TỪNG GIAI ĐOẠN
B16: Giai đoạn | E16: Số hạng mục | F16: Hoàn thành | G16: % Hoàn thành
B17: 1. Khảo sát & Thu thập yêu cầu | E17: =COUNTIF('Master Plan'!$AI$5:$AI$34,$B17) -> 3 | F17: =COUNTIFS('Master Plan'!$AI$5:$AI$34,$B17,'Master Plan'!$J$5:$J$34,"Hoàn thành") -> 0 | G17: =IFERROR(F17/E17,0) -> 0
B18: 2. Phân tích & Thiết kế nghiệp vụ | E18: =COUNTIF('Master Plan'!$AI$5:$AI$34,$B18) -> 3 | F18: =COUNTIFS('Master Plan'!$AI$5:$AI$34,$B18,'Master Plan'!$J$5:$J$34,"Hoàn thành") -> 0 | G18: =IFERROR(F18/E18,0) -> 0
B19: 3. Thiết kế kỹ thuật & UI/UX | E19: =COUNTIF('Master Plan'!$AI$5:$AI$34,$B19) -> 2 | F19: =COUNTIFS('Master Plan'!$AI$5:$AI$34,$B19,'Master Plan'!$J$5:$J$34,"Hoàn thành") -> 0 | G19: =IFERROR(F19/E19,0) -> 0
B20: 4. Soạn thảo & Hoàn thiện tài liệu | E20: =COUNTIF('Master Plan'!$AI$5:$AI$34,$B20) -> 2 | F20: =COUNTIFS('Master Plan'!$AI$5:$AI$34,$B20,'Master Plan'!$J$5:$J$34,"Hoàn thành") -> 0 | G20: =IFERROR(F20/E20,0) -> 0
B21: 5. Xác nhận tài liệu (Confirm) | E21: =COUNTIF('Master Plan'!$AI$5:$AI$34,$B21) -> 3 | F21: =COUNTIFS('Master Plan'!$AI$5:$AI$34,$B21,'Master Plan'!$J$5:$J$34,"Hoàn thành") -> 0 | G21: =IFERROR(F21/E21,0) -> 0
B22: 6. Kick-off dự án | E22: =COUNTIF('Master Plan'!$AI$5:$AI$34,$B22) -> 2 | F22: =COUNTIFS('Master Plan'!$AI$5:$AI$34,$B22,'Master Plan'!$J$5:$J$34,"Hoàn thành") -> 0 | G22: =IFERROR(F22/E22,0) -> 0
B23: 7. Phát triển (Agile Scrum) | E23: =COUNTIF('Master Plan'!$AI$5:$AI$34,$B23) -> 8 | F23: =COUNTIFS('Master Plan'!$AI$5:$AI$34,$B23,'Master Plan'!$J$5:$J$34,"Hoàn thành") -> 0 | G23: =IFERROR(F23/E23,0) -> 0
B24: 8. Kiểm thử hệ thống (SIT) | E24: =COUNTIF('Master Plan'!$AI$5:$AI$34,$B24) -> 1 | F24: =COUNTIFS('Master Plan'!$AI$5:$AI$34,$B24,'Master Plan'!$J$5:$J$34,"Hoàn thành") -> 0 | G24: =IFERROR(F24/E24,0) -> 0
B25: 9. UAT (User Acceptance Testing) | E25: =COUNTIF('Master Plan'!$AI$5:$AI$34,$B25) -> 2 | F25: =COUNTIFS('Master Plan'!$AI$5:$AI$34,$B25,'Master Plan'!$J$5:$J$34,"Hoàn thành") -> 0 | G25: =IFERROR(F25/E25,0) -> 0
B26: 10. Bàn giao & Chuyển giao | E26: =COUNTIF('Master Plan'!$AI$5:$AI$34,$B26) -> 2 | F26: =COUNTIFS('Master Plan'!$AI$5:$AI$34,$B26,'Master Plan'!$J$5:$J$34,"Hoàn thành") -> 0 | G26: =IFERROR(F26/E26,0) -> 0
B27: 11. Nghiệm thu & Bảo hành | E27: =COUNTIF('Master Plan'!$AI$5:$AI$34,$B27) -> 2 | F27: =COUNTIFS('Master Plan'!$AI$5:$AI$34,$B27,'Master Plan'!$J$5:$J$34,"Hoàn thành") -> 0 | G27: =IFERROR(F27/E27,0) -> 0
A29: CHÚ GIẢI TRẠNG THÁI
B30: Chưa bắt đầu | D30: Đang thực hiện | F30: Hoàn thành | H30: Trễ tiến độ

Sheet Master Plan
A1: MASTER PLAN DỰ ÁN SỐ HOÁ TRUNG TÂM BẢO HÀNH – BẢO DƯỠNG "THỎ XING"
A2: App Mobile (Khách hàng) + Web hệ thống (Trung tâm) | Mô hình triển khai: Waterfall (giai đoạn đầu) kết hợp Agile Scrum (giai đoạn phát triển)
K3: TIMELINE DỰ ÁN (THEO TUẦN) — mỗi cột = 1 tuần, màu theo Giai đoạn
A4: STT | B4: Giai đoạn (Phase) | C4: Hạng mục công việc / Sprint | D4: Mô tả ngắn | E4: Người phụ trách | F4: Số ngày | G4: Ngày bắt đầu | H4: Ngày kết thúc | I4: Đầu ra (Deliverable) | J4: Trạng thái | K4: Tuần 1 03/08 | L4: Tuần 2 10/08 | M4: Tuần 3 17/08 | N4: Tuần 4 24/08 | O4: Tuần 5 31/08 | P4: Tuần 6 07/09 | Q4: Tuần 7 14/09 | R4: Tuần 8 21/09 | S4: Tuần 9 28/09 | T4: Tuần 10 05/10 | U4: Tuần 11 12/10 | V4: Tuần 12 19/10 | W4: Tuần 13 26/10 | X4: Tuần 14 02/11 | Y4: Tuần 15 09/11 | Z4: Tuần 16 16/11 | AA4: Tuần 17 23/11 | AB4: Tuần 18 30/11 | AC4: Tuần 19 07/12 | AD4: Tuần 20 14/12 | AE4: Tuần 21 21/12 | AF4: Tuần 22 28/12 | AG4: Tuần 23 04/01 | AI4: Phase (helper)
A5: 1 | B5: 1. Khảo sát & Thu thập yêu cầu | C5: Khảo sát hiện trạng quy trình bảo hành tại trung tâm | D5: Phỏng vấn nhân viên tiếp nhận, thợ, thủ kho; quan sát quy trình thực tế | E5: BA | F5: 3 | G5: =DATE(2026,8,3) -> 46237 | H5: =G5+F5-1 -> 46239 | I5: Biên bản khảo sát hiện trạng | J5: Chưa bắt đầu | AI5: =B5 -> 1. Khảo sát & Thu thập yêu cầu
A6: 2 | C6: Thu thập yêu cầu khách hàng & lãnh đạo | D6: Họp với ban lãnh đạo Thỏ Xing, xác định mục tiêu & phạm vi | E6: BA | F6: 2 | G6: =H5+1 -> 46240 | H6: =G6+F6-1 -> 46241 | J6: Chưa bắt đầu | AI6: =IF(B6<>"",B6,AI5) -> 1. Khảo sát & Thu thập yêu cầu
A7: 3 | C7: Benchmark giải pháp tương tự trên thị trường | D7: Tham khảo app/web quản lý bảo hành của các chuỗi khác | E7: BA | F7: 2 | G7: =H6+1 -> 46242 | H7: =G7+F7-1 -> 46243 | J7: Chưa bắt đầu | AI7: =IF(B7<>"",B7,AI6) -> 1. Khảo sát & Thu thập yêu cầu
A8: 4 | B8: 2. Phân tích & Thiết kế nghiệp vụ | C8: Xây dựng BRD (Business Requirement Document) | D8: Tài liệu yêu cầu nghiệp vụ tổng thể | E8: BA | F8: 3 | G8: =H7+1 -> 46244 | H8: =G8+F8-1 -> 46246 | I8: BRD (Business Requirement Document) | J8: Chưa bắt đầu | AI8: =IF(B8<>"",B8,AI7) -> 2. Phân tích & Thiết kế nghiệp vụ
A9: 5 | C9: Xây dựng Function List (2 cấp) & Use Case Spec | D9: Bóc tách chức năng lớn/nhỏ, viết đặc tả use case | E9: BA | F9: 3 | G9: =H8+1 -> 46247 | H9: =G9+F9-1 -> 46249 | I9: Function List 2 cấp + Use Case Spec | J9: Chưa bắt đầu | AI9: =IF(B9<>"",B9,AI8) -> 2. Phân tích & Thiết kế nghiệp vụ
A10: 6 | C10: Vẽ Business Process Flow & 5 luồng chức năng chính | D10: Sơ đồ nghiệp vụ tổng thể + flowchart chi tiết | E10: BA | F10: 2 | G10: =H9+1 -> 46250 | H10: =G10+F10-1 -> 46251 | I10: Business Process Chart + 5 Flowchart | J10: Chưa bắt đầu | AI10: =IF(B10<>"",B10,AI9) -> 2. Phân tích & Thiết kế nghiệp vụ
A11: 7 | B11: 3. Thiết kế kỹ thuật & UI/UX | C11: Thiết kế UI/UX (Wireframe → Mockup → Prototype) | D11: Thiết kế màn hình App & Web, prototype tương tác | E11: UI/UX Designer | F11: 5 | G11: =H10+1 -> 46252 | H11: =G11+F11-1 -> 46256 | I11: Wireframe/Mockup/Prototype UI-UX | J11: Chưa bắt đầu | AI11: =IF(B11<>"",B11,AI10) -> 3. Thiết kế kỹ thuật & UI/UX
A12: 8 | C12: Thiết kế kiến trúc hệ thống & ERD | D12: SRS kỹ thuật, sơ đồ kiến trúc, thiết kế CSDL | E12: Solution Architect | F12: 4 | G12: =H11+1 -> 46257 | H12: =G12+F12-1 -> 46260 | I12: SRS kỹ thuật + ERD | J12: Chưa bắt đầu | AI12: =IF(B12<>"",B12,AI11) -> 3. Thiết kế kỹ thuật & UI/UX
A13: 9 | B13: 4. Soạn thảo & Hoàn thiện tài liệu | C13: Tổng hợp BRD + SRS + UI/UX thành bộ hồ sơ hoàn chỉnh | D13: Chuẩn hoá & trình bày thống nhất toàn bộ tài liệu | E13: BA | F13: 2 | G13: =H12+1 -> 46261 | H13: =G13+F13-1 -> 46262 | I13: Bộ hồ sơ yêu cầu hoàn chỉnh | J13: Chưa bắt đầu | AI13: =IF(B13<>"",B13,AI12) -> 4. Soạn thảo & Hoàn thiện tài liệu
A14: 10 | C14: Review nội bộ (QA tài liệu) | D14: PM/Lead rà soát chất lượng & tính nhất quán tài liệu | E14: PM/Team Lead | F14: 1 | G14: =H13+1 -> 46263 | H14: =G14+F14-1 -> 46263 | J14: Chưa bắt đầu | AI14: =IF(B14<>"",B14,AI13) -> 4. Soạn thảo & Hoàn thiện tài liệu
A15: 11 | B15: 5. Xác nhận tài liệu (Confirm) | C15: Trình bày tài liệu cho khách hàng Thỏ Xing | D15: Buổi họp trình bày BRD/SRS/UI cho khách hàng | E15: BA/PM | F15: 1 | G15: =H14+1 -> 46264 | H15: =G15+F15-1 -> 46264 | J15: Chưa bắt đầu | AI15: =IF(B15<>"",B15,AI14) -> 5. Xác nhận tài liệu (Confirm)
A16: 12 | C16: Thu thập phản hồi & chỉnh sửa tài liệu | D16: Điều chỉnh theo góp ý của khách hàng | E16: BA | F16: 2 | G16: =H15+1 -> 46265 | H16: =G16+F16-1 -> 46266 | J16: Chưa bắt đầu | AI16: =IF(B16<>"",B16,AI15) -> 5. Xác nhận tài liệu (Confirm)
A17: 13 | C17: Khách hàng ký xác nhận (Sign-off) | D17: Chốt phạm vi & baseline yêu cầu chính thức | E17: Khách hàng / PM | F17: 1 | G17: =H16+1 -> 46267 | H17: =G17+F17-1 -> 46267 | I17: Biên bản Sign-off yêu cầu | J17: Chưa bắt đầu | AI17: =IF(B17<>"",B17,AI16) -> 5. Xác nhận tài liệu (Confirm)
A18: 14 | B18: 6. Kick-off dự án | C18: Họp Kick-off nội bộ đội dự án | D18: Phổ biến mục tiêu, phạm vi, vai trò cho toàn đội | E18: PM | F18: 1 | G18: =H17+1 -> 46268 | H18: =G18+F18-1 -> 46268 | I18: Biên bản Kick-off | J18: Chưa bắt đầu | AI18: =IF(B18<>"",B18,AI17) -> 6. Kick-off dự án
A19: 15 | C19: Chuyển giao (Transfer) tài liệu cho đội phát triển | D19: Bàn giao BRD/SRS/UI/UX & Function List cho Dev Team | E19: BA → Dev Team | F19: 1 | G19: =H18+1 -> 46269 | H19: =G19+F19-1 -> 46269 | I19: Biên bản bàn giao yêu cầu cho Dev | J19: Chưa bắt đầu | AI19: =IF(B19<>"",B19,AI18) -> 6. Kick-off dự án
A20: 16 | B20: 7. Phát triển (Agile Scrum) | C20: Sprint 0 – Setup môi trường & kiến trúc nền tảng | D20: Khởi tạo repo, CI/CD, cấu hình môi trường Dev/Staging | E20: Dev Team | F20: 5 | G20: =H19+1 -> 46270 | H20: =G20+F20-1 -> 46274 | I20: Môi trường Dev/Staging + CI/CD | J20: Chưa bắt đầu | AI20: =IF(B20<>"",B20,AI19) -> 7. Phát triển (Agile Scrum)
A21: 17 | C21: Sprint 1 – Module Tài khoản & Đăng nhập (App+Web) | D21: Đăng ký/đăng nhập, phân quyền, hồ sơ người dùng | E21: Dev Team | F21: 10 | G21: =H20+1 -> 46275 | H21: =G21+F21-1 -> 46284 | I21: Module Tài khoản (App+Web) | J21: Chưa bắt đầu | AI21: =IF(B21<>"",B21,AI20) -> 7. Phát triển (Agile Scrum)
A22: 18 | C22: Sprint 2 – Module Đặt lịch & Tiếp nhận đơn | D22: App đặt lịch bảo hành; Web tiếp nhận & xác nhận đơn | E22: Dev Team | F22: 10 | G22: =H21+1 -> 46285 | H22: =G22+F22-1 -> 46294 | I22: Module Đặt lịch & Tiếp nhận đơn | J22: Chưa bắt đầu | AI22: =IF(B22<>"",B22,AI21) -> 7. Phát triển (Agile Scrum)
A23: 19 | C23: Sprint 3 – Module Điều phối thợ | D23: Gán thợ, lịch làm việc thợ, thông báo điều phối | E23: Dev Team | F23: 10 | G23: =H22+1 -> 46295 | H23: =G23+F23-1 -> 46304 | I23: Module Điều phối thợ | J23: Chưa bắt đầu | AI23: =IF(B23<>"",B23,AI22) -> 7. Phát triển (Agile Scrum)
A24: 20 | C24: Sprint 4 – Module Kho linh kiện & Cấp phát | D24: Quản lý tồn kho, yêu cầu & duyệt cấp phát linh kiện | E24: Dev Team | F24: 10 | G24: =H23+1 -> 46305 | H24: =G24+F24-1 -> 46314 | I24: Module Kho & Cấp phát linh kiện | J24: Chưa bắt đầu | AI24: =IF(B24<>"",B24,AI23) -> 7. Phát triển (Agile Scrum)
A25: 21 | C25: Sprint 5 – Module Theo dõi tiến độ & Thông báo | D25: Timeline trạng thái đơn, push notification, đánh giá | E25: Dev Team | F25: 10 | G25: =H24+1 -> 46315 | H25: =G25+F25-1 -> 46324 | I25: Module Theo dõi tiến độ & Thông báo | J25: Chưa bắt đầu | AI25: =IF(B25<>"",B25,AI24) -> 7. Phát triển (Agile Scrum)
A26: 22 | C26: Sprint 6 – Báo cáo, thống kê & hoàn thiện | D26: Dashboard, báo cáo hiệu suất, hoàn thiện UI toàn hệ thống | E26: Dev Team | F26: 10 | G26: =H25+1 -> 46325 | H26: =G26+F26-1 -> 46334 | I26: Module Báo cáo & Dashboard | J26: Chưa bắt đầu | AI26: =IF(B26<>"",B26,AI25) -> 7. Phát triển (Agile Scrum)
A27: 23 | C27: Sprint 7 – Buffer, sửa lỗi & tối ưu hiệu năng | D27: Regression fix, tối ưu tốc độ, chuẩn bị release | E27: Dev Team | F27: 5 | G27: =H26+1 -> 46335 | H27: =G27+F27-1 -> 46339 | I27: Build ổn định, sẵn sàng release | J27: Chưa bắt đầu | AI27: =IF(B27<>"",B27,AI26) -> 7. Phát triển (Agile Scrum)
A28: 24 | B28: 8. Kiểm thử hệ thống (SIT) | C28: System Integration Testing | D28: Kiểm thử tích hợp toàn bộ App + Web + API | E28: QA Team | F28: 5 | G28: =H27+1 -> 46340 | H28: =G28+F28-1 -> 46344 | I28: Báo cáo kết quả SIT | J28: Chưa bắt đầu | AI28: =IF(B28<>"",B28,AI27) -> 8. Kiểm thử hệ thống (SIT)
A29: 25 | B29: 9. UAT (User Acceptance Testing) | C29: Khách hàng kiểm thử nghiệm thu chức năng | D29: Thỏ Xing trực tiếp thử nghiệm theo kịch bản UAT | E29: Khách hàng + QA | F29: 5 | G29: =H28+1 -> 46345 | H29: =G29+F29-1 -> 46349 | I29: Biên bản UAT | J29: Chưa bắt đầu | AI29: =IF(B29<>"",B29,AI28) -> 9. UAT (User Acceptance Testing)
A30: 26 | C30: Tổng hợp lỗi & chỉnh sửa theo phản hồi UAT | D30: Fix bug phát sinh trong quá trình UAT | E30: Dev Team | F30: 3 | G30: =H29+1 -> 46350 | H30: =G30+F30-1 -> 46352 | I30: Bug list đã fix, build UAT v2 | J30: Chưa bắt đầu | AI30: =IF(B30<>"",B30,AI29) -> 9. UAT (User Acceptance Testing)
A31: 27 | B31: 10. Bàn giao & Chuyển giao | C31: Triển khai lên môi trường Production | D31: Deploy chính thức, cấu hình domain/server thật | E31: DevOps | F31: 2 | G31: =H30+1 -> 46353 | H31: =G31+F31-1 -> 46354 | I31: Hệ thống Production live | J31: Chưa bắt đầu | AI31: =IF(B31<>"",B31,AI30) -> 10. Bàn giao & Chuyển giao
A32: 28 | C32: Đào tạo & bàn giao vận hành cho Thỏ Xing | D32: Training nhân viên tiếp nhận, điều phối, thủ kho, quản lý | E32: PM/BA | F32: 2 | G32: =H31+1 -> 46355 | H32: =G32+F32-1 -> 46356 | I32: Tài liệu hướng dẫn sử dụng + đội ngũ được đào tạo | J32: Chưa bắt đầu | AI32: =IF(B32<>"",B32,AI31) -> 10. Bàn giao & Chuyển giao
A33: 29 | B33: 11. Nghiệm thu & Bảo hành | C33: Ký biên bản nghiệm thu dự án | D33: Xác nhận hoàn thành theo hợp đồng | E33: PM/Khách hàng | F33: 1 | G33: =H32+1 -> 46357 | H33: =G33+F33-1 -> 46357 | I33: Biên bản nghiệm thu dự án | J33: Chưa bắt đầu | AI33: =IF(B33<>"",B33,AI32) -> 11. Nghiệm thu & Bảo hành
A34: 30 | C34: Bảo hành & hỗ trợ kỹ thuật sau bàn giao | D34: Hỗ trợ sửa lỗi, theo dõi vận hành ổn định | E34: Dev Team | F34: 30 | G34: =H33+1 -> 46358 | H34: =G34+F34-1 -> 46387 | I34: Báo cáo bảo hành định kỳ | J34: Chưa bắt đầu | AI34: =IF(B34<>"",B34,AI33) -> 11. Nghiệm thu & Bảo hành
B36: Chú giải màu Timeline (theo Giai đoạn) — xem chi tiết bên dưới
B37: CHÚ GIẢI MÀU SẮC THEO GIAI ĐOẠN | G37: CHÚ GIẢI TRẠNG THÁI
B38: 1. Khảo sát & Thu thập yêu cầu | H38: Chưa bắt đầu
B39: 2. Phân tích & Thiết kế nghiệp vụ | H39: Đang thực hiện
B40: 3. Thiết kế kỹ thuật & UI/UX | H40: Hoàn thành
B41: 4. Soạn thảo & Hoàn thiện tài liệu | H41: Trễ tiến độ
...

Sheet Ghi chú & Giả định
A1: GHI CHÚ & GIẢ ĐỊNH CỦA MASTER PLAN
A4: 1 | B4: Ngày bắt đầu dự án giả định là 03/08/2026 (Thứ Hai) — có thể chỉnh sửa tại ô G5, toàn bộ lịch trình sẽ tự động dịch chuyển theo (các ô Ngày bắt đầu/kết thúc dùng công thức liên kết chuỗi).
A6: 2 | B6: Số ngày (cột F) tính theo NGÀY LÀM VIỆC LIÊN TỤC ước lượng — nhóm dự án nên điều chỉnh lại theo năng lực đội ngũ thực tế và ngày nghỉ lễ.
A8: 3 | B8: Giai đoạn 7 (Phát triển) áp dụng Agile Scrum, mỗi Sprint thường quy ước 2 tuần (10 ngày làm việc), riêng Sprint 0 và Sprint 7 rút gọn còn 1 tuần (buffer/setup).
A10: 4 | B10: Cột 'Trạng thái' là danh sách thả xuống (dropdown) để đội dự án cập nhật tiến độ thực tế trong quá trình triển khai.
A12: 5 | B12: Tổng thời gian ước tính toàn dự án: từ Khảo sát đến Nghiệm thu (chưa gồm 30 ngày bảo hành) khoảng 4.5 - 5 tháng — cần Khách hàng và đội dự án xác nhận lại mức độ khả thi.
A14: 6 | B14: Đây là kế hoạch sơ bộ (baseline) phục vụ trình bày & thống nhất phạm vi — cần review chi tiết hơn theo effort estimation thực tế (Planning Poker) trước khi cam kết chính thức với khách hàng.
